Traceback (most recent call last):
  File "/home/shrihan/weaklens/gaia_match_psf/gaia_match_psf_code/src/gaiamatch_des_g.py", line 76, in <module>
    master_comb_df = match.concatenate_int_data(INT_DATA_PATH)
  File "/home/shrihan/weaklens/gaia_match_psf/gaia_match_psf_code/src/match.py", line 290, in concatenate_int_data
    df_list.append(pd.read_csv(fold + file, index_col=0))
  File "/home/shrihan/.conda/envs/weaklens2/lib/python3.10/site-packages/pandas/io/parsers/readers.py", line 948, in read_csv
    return _read(filepath_or_buffer, kwds)
  File "/home/shrihan/.conda/envs/weaklens2/lib/python3.10/site-packages/pandas/io/parsers/readers.py", line 611, in _read
    parser = TextFileReader(filepath_or_buffer, **kwds)
  File "/home/shrihan/.conda/envs/weaklens2/lib/python3.10/site-packages/pandas/io/parsers/readers.py", line 1448, in __init__
    self._engine = self._make_engine(f, self.engine)
  File "/home/shrihan/.conda/envs/weaklens2/lib/python3.10/site-packages/pandas/io/parsers/readers.py", line 1705, in _make_engine
    self.handles = get_handle(
  File "/home/shrihan/.conda/envs/weaklens2/lib/python3.10/site-packages/pandas/io/common.py", line 863, in get_handle
    handle = open(
IsADirectoryError: [Errno 21] Is a directory: '../../int_data/rdata'
